Workbook

Sheet Google Leads 
A1: Matricule | B1: Nom De l'agent | C1: Hr début shift Réalisée | D1: Hr début shift Planifiée | E1: Hr fin shift Réalisée | F1: Hr Fin shift Planifiée | G1: Durée de la Pause Dej | H1: Dépsement des pauses | I1: Retard Debut de shift | J1: Retard Dej | K1: Somme des retards | L1: Départs Anticipés | M1: Absences | N1: Hr Adherée | O1: Hr Planifiée | P1: Segment | Q1: Date | R1: Hr Abs Pure | S1: Hr Abs Totales | T1: Semaine | U1: Mois | V1: Année | W1: VTO | X1: Heures SUP | Y1: Team | Z1: Business | AA1: Statut | AB1: Congé payé | AC1: Congé sans solde | AD1: Congé spécial | AE1: Jour férié | AF1: Commentaire | AG1: Plannif spécial
A2: =VLOOKUP(B2,Annuaire_roster!B:F,5,0) -> 742 | B2: ZAKI OMAR | C2: =IFERROR(IF(COUNTIFS(Pointage_brut!$E:$E,VLOOKUP($B2,Annuaire_roster!$B:$J,9,0),Pointage_brut!$A:$A,TEXT($Q2,"yyyymmdd")*1)=0,"",MOD(_xlfn.MINIFS(Pointage_brut!$F:$F,Pointage_brut!$E:$E,VLOOKUP($B2,Annuaire_roster!$B:$J,9,0),Pointage_brut!$A:$A,TEXT($Q2,"yyyymmdd")*1),1)),"") | D2: {=IFERROR(INDEX(Planning2[],MATCH(1,(Planning2[Nom]=B2)*(Planning2[Date]=Q2),0),3),"-")} -> 0.29166667 | E2: =IFERROR(IF(COUNTIFS(Pointage_brut!$E:$E,VLOOKUP($B2,Annuaire_roster!$B:$J,9,0),Pointage_brut!$A:$A,TEXT($Q2,"yyyymmdd")*1)=0,"",MOD(_xlfn.MAXIFS(Pointage_brut!$G:$G,Pointage_brut!$E:$E,VLOOKUP($B2,Annuaire_roster!$B:$J,9,0),Pointage_brut!$A:$A,TEXT($Q2,"yyyymmdd")*1),1)),"") | F2: {=IFERROR(INDEX(Planning2[],MATCH(1,(Planning2[Nom]=B2)*(Planning2[Date]=Q2),0),4),"-")} -> 0.66666667 | I2: =IF(IF(OR(C2="",D2="Congé",D2="OFF",D2="Congé spécial"),"",IF(D2>F2,D2-C2,IF(C2-D2<0,0,C2-D2)))<0.00068287037037037,"",IF(OR(D2="Congé",D2="OFF",C2="",D2="Congé spécial"),"",IF(D2>F2,D2-C2,IF(C2-D2<0,0,C2-D2)))) | K2: =IF(SUM(H2:J2)<0.00068287037037037,0,SUM(H2:J2)) -> 0 | L2: =IF(OR(F2="Congé",F2="OFF",M2="Abs",F2="Congé sans solde",F2="Férié",F2="Congé spécial",D2="Congé spécial"),0,IF(F2-E2<0,0,IF(F2-E2<=0.00068287037037037,0,F2-E2))) -> 0 | M2: =IF(AND(O2<>0,C2=""),"Abs",0) -> Abs | N2: =IFERROR(IF(OR(D2="OFF",D2="Congé",M2="Abs",D2="Congé sans solde",D2="Férié"),"",IF(O2-K2-L2>O2,O2,IF(O2-K2-L2<0,"",O2-K2-L2))),"") | O2: =IF(AG2="2H Pause déjeuner",IF(F2-D2-0.0833333333333333<0,F2-D2-0.0833333333333333+1,F2-D2-0.0833333333333333),IF(OR(AND(F2="OFF",D2="OFF"),AND(F2="Congé",D2="Congé"),AND(F2="Congé sans solde",D2="Congé sans solde"),AND(F2="Congé spécial",D2="Congé spécial"),AND(F2="Férié",D2="Férié"),AND(F2="OFF",D2="Congé"),AND(F2="OFF",D2="Congé sans solde"),AND(F2="OFF",D2="Congé spécial"),AND(F2="OFF",D2="Férié"),AND(F2="Congé",D2="OFF"),AND(F2="Congé",D2="Congé sans solde"),AND(F2="Congé",D2="Congé spécial"),AND(F2="Congé",D2="Férié"),AND(F2="Congé sans solde",D2="OFF"),AND(F2="Congé sans solde",D2="Congé"),AND(F2="Congé sans solde",D2="Congé spécial"),AND(F2="Congé sans solde",D2="Férié"),AND(F2="Congé spécial",D2="OFF"),AND(F2="Congé spécial",D2="Congé"),AND(F2="Congé spécial",D2="Congé sans solde"),AND(F2="Congé spécial",D2="Férié"),AND(F2="Férié",D2="OFF"),AND(F2="Férié",D2="Congé"),AND(F2="Férié",D2="Congé sans solde"),AND(F2="Férié",D2="Congé spécial")),0,IF(OR(F2="OFF",F2="Congé",F2="Congé spécial",F2="Congé sans solde",D2="OFF",D2="Congé",D2="Congé spécial",D2="Congé sans solde"),0.208333333333334,IF(AND(AG2="",F2-D2<0),("24:00:00"-D2)+("00:00:00"+F2)-0.0416666666666667,IF(AND(OR(AG2="Allaitement",AG2="Sans déjeuner"),F2-D2<0),("24:00:00"-D2)+("00:00:00"+F2),IF(AND(AG2="",F2-D2>0.166666666666667),F2-D2-0.0416666666666667,IF(AND(OR(AG2="Allaitement",AG2="Sans déjeuner"),F2-D2>0.166666666666667),F2-D2,F2-D2))))))) -> 0.33333333 | P2: =IFERROR(VLOOKUP($B2,Annuaire_roster!$B:$G,MATCH(P$1,Annuaire_roster!$B$1:$G$1,0),0),"-") -> Google Leads | Q2: 44717 | R2: =IF(M2="Abs",O2,0) -> 0.33333333 | S2: =SUM(R2,L2,I2,J2,W2,H2) -> 0.33333333 | T2: ="Sem - "&WEEKNUM(Q2,21) -> Sem - 23 | U2: =PROPER(TEXT(Q2,"mmmm")) -> June | V2: =+TEXT(Q2,"aaa") -> Sat | X2: =IFERROR(IF(M2="Abs",0,IF((D2-C2+E2-F2)<0.000694444444444444,0,(D2-C2+E2-F2))),0) -> 0 | Y2: =IFERROR(VLOOKUP(B2,Annuaire_roster!B:E,4,0),"-") -> OUAQERROUCH Nour-El Houda | Z2: =IFERROR(VLOOKUP(B2,Annuaire_roster!B:F,3,0),"-") -> Google Leads | AA2: =IFERROR(VLOOKUP(B2,Annuaire_roster!B:I,6,0),"-") -> Forfaitaire | AB2: =IF(AND(D2="Congé",F2="Congé"),0.333333333333333,IF(OR(AND(D2="Congé",F2<>"Congé"),(AND(F2="Congé",D2<>"Congé"))),0.166666666666667,"")) | AC2: =IF(AND(D2="Congé sans solde",F2="Congé sans solde"),0.333333333333333,IF(OR(AND(D2="Congé sans solde",F2<>"Congé sans solde"),(AND(F2="Congé sans solde",D2<>"Congé sans solde"))),0.166666666666667,"")) | AD2: =IF(AND(D2="Congé spécial",F2="Congé spécial"),0.333333333333333,IF(OR(AND(D2="Congé spécial",F2<>"Congé décès"),(AND(F2="Congé spécial",D2<>"Congé spécial"))),0.166666666666667,"")) | AE2: =IF(AND(D2="Férié",F2="Férié"),0.333333333333333,IF(OR(AND(D2="Férié",F2<>"Férié"),(AND(F2="Férié",D2<>"Férié"))),0.166666666666667,""))
A3: =VLOOKUP(B3,Annuaire_roster!B:F,5,0) -> 0 | B3: AZHARI ABDELHAMID | C3: =IFERROR(IF(COUNTIFS(Pointage_brut!$E:$E,VLOOKUP($B3,Annuaire_roster!$B:$J,9,0),Pointage_brut!$A:$A,TEXT($Q3,"yyyymmdd")*1)=0,"",MOD(_xlfn.MINIFS(Pointage_brut!$F:$F,Pointage_brut!$E:$E,VLOOKUP($B3,Annuaire_roster!$B:$J,9,0),Pointage_brut!$A:$A,TEXT($Q3,"yyyymmdd")*1),1)),"") | D3: {=IFERROR(INDEX(Planning2[],MATCH(1,(Planning2[Nom]=B3)*(Planning2[Date]=Q3),0),3),"-")} -> 0.29166667 | E3: =IFERROR(IF(COUNTIFS(Pointage_brut!$E:$E,VLOOKUP($B3,Annuaire_roster!$B:$J,9,0),Pointage_brut!$A:$A,TEXT($Q3,"yyyymmdd")*1)=0,"",MOD(_xlfn.MAXIFS(Pointage_brut!$G:$G,Pointage_brut!$E:$E,VLOOKUP($B3,Annuaire_roster!$B:$J,9,0),Pointage_brut!$A:$A,TEXT($Q3,"yyyymmdd")*1),1)),"") | F3: {=IFERROR(INDEX(Planning2[],MATCH(1,(Planning2[Nom]=B3)*(Planning2[Date]=Q3),0),4),"-")} -> 0.70833333 | I3: =IF(IF(OR(C3="",D3="Congé",D3="OFF",D3="Congé spécial"),"",IF(D3>F3,D3-C3,IF(C3-D3<0,0,C3-D3)))<0.00068287037037037,"",IF(OR(D3="Congé",D3="OFF",C3="",D3="Congé spécial"),"",IF(D3>F3,D3-C3,IF(C3-D3<0,0,C3-D3)))) | K3: =IF(SUM(H3:J3)<0.00068287037037037,0,SUM(H3:J3)) -> 0 | L3: =IF(OR(F3="Congé",F3="OFF",M3="Abs",F3="Congé sans solde",F3="Férié",F3="Congé spécial",D3="Congé spécial"),0,IF(F3-E3<0,0,IF(F3-E3<=0.00068287037037037,0,F3-E3))) -> 0 | M3: =IF(AND(O3<>0,C3=""),"Abs",0) -> Abs | N3: =IFERROR(IF(OR(D3="OFF",D3="Congé",M3="Abs",D3="Congé sans solde",D3="Férié"),"",IF(O3-K3-L3>O3,O3,IF(O3-K3-L3<0,"",O3-K3-L3))),"") | O3: =IF(AG3="2H Pause déjeuner",IF(F3-D3-0.0833333333333333<0,F3-D3-0.0833333333333333+1,F3-D3-0.0833333333333333),IF(OR(AND(F3="OFF",D3="OFF"),AND(F3="Congé",D3="Congé"),AND(F3="Congé sans solde",D3="Congé sans solde"),AND(F3="Congé spécial",D3="Congé spécial"),AND(F3="Férié",D3="Férié"),AND(F3="OFF",D3="Congé"),AND(F3="OFF",D3="Congé sans solde"),AND(F3="OFF",D3="Congé spécial"),AND(F3="OFF",D3="Férié"),AND(F3="Congé",D3="OFF"),AND(F3="Congé",D3="Congé sans solde"),AND(F3="Congé",D3="Congé spécial"),AND(F3="Congé",D3="Férié"),AND(F3="Congé sans solde",D3="OFF"),AND(F3="Congé sans solde",D3="Congé"),AND(F3="Congé sans solde",D3="Congé spécial"),AND(F3="Congé sans solde",D3="Férié"),AND(F3="Congé spécial",D3="OFF"),AND(F3="Congé spécial",D3="Congé"),AND(F3="Congé spécial",D3="Congé sans solde"),AND(F3="Congé spécial",D3="Férié"),AND(F3="Férié",D3="OFF"),AND(F3="Férié",D3="Congé"),AND(F3="Férié",D3="Congé sans solde"),AND(F3="Férié",D3="Congé spécial")),0,IF(OR(F3="OFF",F3="Congé",F3="Congé spécial",F3="Congé sans solde",D3="OFF",D3="Congé",D3="Congé spécial",D3="Congé sans solde"),0.208333333333334,IF(AND(AG3="",F3-D3<0),("24:00:00"-D3)+("00:00:00"+F3)-0.0416666666666667,IF(AND(OR(AG3="Allaitement",AG3="Sans déjeuner"),F3-D3<0),("24:00:00"-D3)+("00:00:00"+F3),IF(AND(AG3="",F3-D3>0.166666666666667),F3-D3-0.0416666666666667,IF(AND(OR(AG3="Allaitement",AG3="Sans déjeuner"),F3-D3>0.166666666666667),F3-D3,F3-D3))))))) -> 0.375 | P3: =IFERROR(VLOOKUP($B3,Annuaire_roster!$B:$G,MATCH(P$1,Annuaire_roster!$B$1:$G$1,0),0),"-") -> Google Leads | Q3: 44717 | R3: =IF(M3="Abs",O3,0) -> 0.375 | S3: =SUM(R3,L3,I3,J3,W3,H3) -> 0.375 | T3: ="Sem - "&WEEKNUM(Q3,21) -> Sem - 23 | U3: =PROPER(TEXT(Q3,"mmmm")) -> June | V3: =+TEXT(Q3,"aaa") -> Sat | X3: =IFERROR(IF(M3="Abs",0,IF((D3-C3+E3-F3)<0.000694444444444444,0,(D3-C3+E3-F3))),0) -> 0 | Y3: =IFERROR(VLOOKUP(B3,Annuaire_roster!B:E,4,0),"-") -> 0 | Z3: =IFERROR(VLOOKUP(B3,Annuaire_roster!B:F,3,0),"-") -> Google Leads | AA3: =IFERROR(VLOOKUP(B3,Annuaire_roster!B:I,6,0),"-") -> 0 | AB3: =IF(AND(D3="Congé",F3="Congé"),0.333333333333333,IF(OR(AND(D3="Congé",F3<>"Congé"),(AND(F3="Congé",D3<>"Congé"))),0.166666666666667,"")) | AC3: =IF(AND(D3="Congé sans solde",F3="Congé sans solde"),0.333333333333333,IF(OR(AND(D3="Congé sans solde",F3<>"Congé sans solde"),(AND(F3="Congé sans solde",D3<>"Congé sans solde"))),0.166666666666667,"")) | AD3: =IF(AND(D3="Congé spécial",F3="Congé spécial"),0.333333333333333,IF(OR(AND(D3="Congé spécial",F3<>"Congé décès"),(AND(F3="Congé spécial",D3<>"Congé spécial"))),0.166666666666667,"")) | AE3: =IF(AND(D3="Férié",F3="Férié"),0.333333333333333,IF(OR(AND(D3="Férié",F3<>"Férié"),(AND(F3="Férié",D3<>"Férié"))),0.166666666666667,""))
A4: =VLOOKUP(B4,Annuaire_roster!B:F,5,0) -> 0 | B4: LALOUN MANAL | C4: =IFERROR(IF(COUNTIFS(Pointage_brut!$E:$E,VLOOKUP($B4,Annuaire_roster!$B:$J,9,0),Pointage_brut!$A:$A,TEXT($Q4,"yyyymmdd")*1)=0,"",MOD(_xlfn.MINIFS(Pointage_brut!$F:$F,Pointage_brut!$E:$E,VLOOKUP($B4,Annuaire_roster!$B:$J,9,0),Pointage_brut!$A:$A,TEXT($Q4,"yyyymmdd")*1),1)),"") | D4: {=IFERROR(INDEX(Planning2[],MATCH(1,(Planning2[Nom]=B4)*(Planning2[Date]=Q4),0),3),"-")} -> 0.29166667 | E4: =IFERROR(IF(COUNTIFS(Pointage_brut!$E:$E,VLOOKUP($B4,Annuaire_roster!$B:$J,9,0),Pointage_brut!$A:$A,TEXT($Q4,"yyyymmdd")*1)=0,"",MOD(_xlfn.MAXIFS(Pointage_brut!$G:$G,Pointage_brut!$E:$E,VLOOKUP($B4,Annuaire_roster!$B:$J,9,0),Pointage_brut!$A:$A,TEXT($Q4,"yyyymmdd")*1),1)),"") | F4: {=IFERROR(INDEX(Planning2[],MATCH(1,(Planning2[Nom]=B4)*(Planning2[Date]=Q4),0),4),"-")} -> 0.70833333 | I4: =IF(IF(OR(C4="",D4="Congé",D4="OFF",D4="Congé spécial"),"",IF(D4>F4,D4-C4,IF(C4-D4<0,0,C4-D4)))<0.00068287037037037,"",IF(OR(D4="Congé",D4="OFF",C4="",D4="Congé spécial"),"",IF(D4>F4,D4-C4,IF(C4-D4<0,0,C4-D4)))) | K4: =IF(SUM(H4:J4)<0.00068287037037037,0,SUM(H4:J4)) -> 0 | L4: =IF(OR(F4="Congé",F4="OFF",M4="Abs",F4="Congé sans solde",F4="Férié",F4="Congé spécial",D4="Congé spécial"),0,IF(F4-E4<0,0,IF(F4-E4<=0.00068287037037037,0,F4-E4))) -> 0 | M4: =IF(AND(O4<>0,C4=""),"Abs",0) -> Abs | N4: =IFERROR(IF(OR(D4="OFF",D4="Congé",M4="Abs",D4="Congé sans solde",D4="Férié"),"",IF(O4-K4-L4>O4,O4,IF(O4-K4-L4<0,"",O4-K4-L4))),"") | O4: =IF(AG4="2H Pause déjeuner",IF(F4-D4-0.0833333333333333<0,F4-D4-0.0833333333333333+1,F4-D4-0.0833333333333333),IF(OR(AND(F4="OFF",D4="OFF"),AND(F4="Congé",D4="Congé"),AND(F4="Congé sans solde",D4="Congé sans solde"),AND(F4="Congé spécial",D4="Congé spécial"),AND(F4="Férié",D4="Férié"),AND(F4="OFF",D4="Congé"),AND(F4="OFF",D4="Congé sans solde"),AND(F4="OFF",D4="Congé spécial"),AND(F4="OFF",D4="Férié"),AND(F4="Congé",D4="OFF"),AND(F4="Congé",D4="Congé sans solde"),AND(F4="Congé",D4="Congé spécial"),AND(F4="Congé",D4="Férié"),AND(F4="Congé sans solde",D4="OFF"),AND(F4="Congé sans solde",D4="Congé"),AND(F4="Congé sans solde",D4="Congé spécial"),AND(F4="Congé sans solde",D4="Férié"),AND(F4="Congé spécial",D4="OFF"),AND(F4="Congé spécial",D4="Congé"),AND(F4="Congé spécial",D4="Congé sans solde"),AND(F4="Congé spécial",D4="Férié"),AND(F4="Férié",D4="OFF"),AND(F4="Férié",D4="Congé"),AND(F4="Férié",D4="Congé sans solde"),AND(F4="Férié",D4="Congé spécial")),0,IF(OR(F4="OFF",F4="Congé",F4="Congé spécial",F4="Congé sans solde",D4="OFF",D4="Congé",D4="Congé spécial",D4="Congé sans solde"),0.208333333333334,IF(AND(AG4="",F4-D4<0),("24:00:00"-D4)+("00:00:00"+F4)-0.0416666666666667,IF(AND(OR(AG4="Allaitement",AG4="Sans déjeuner"),F4-D4<0),("24:00:00"-D4)+("00:00:00"+F4),IF(AND(AG4="",F4-D4>0.166666666666667),F4-D4-0.0416666666666667,IF(AND(OR(AG4="Allaitement",AG4="Sans déjeuner"),F4-D4>0.166666666666667),F4-D4,F4-D4))))))) -> 0.375 | P4: =IFERROR(VLOOKUP($B4,Annuaire_roster!$B:$G,MATCH(P$1,Annuaire_roster!$B$1:$G$1,0),0),"-") -> Google Leads | Q4: 44717 | R4: =IF(M4="Abs",O4,0) -> 0.375 | S4: =SUM(R4,L4,I4,J4,W4,H4) -> 0.375 | T4: ="Sem - "&WEEKNUM(Q4,21) -> Sem - 23 | U4: =PROPER(TEXT(Q4,"mmmm")) -> June | V4: =+TEXT(Q4,"aaa") -> Sat | X4: =IFERROR(IF(M4="Abs",0,IF((D4-C4+E4-F4)<0.000694444444444444,0,(D4-C4+E4-F4))),0) -> 0 | Y4: =IFERROR(VLOOKUP(B4,Annuaire_roster!B:E,4,0),"-") -> 0 | Z4: =IFERROR(VLOOKUP(B4,Annuaire_roster!B:F,3,0),"-") -> Google Leads | AA4: =IFERROR(VLOOKUP(B4,Annuaire_roster!B:I,6,0),"-") -> 0 | AB4: =IF(AND(D4="Congé",F4="Congé"),0.333333333333333,IF(OR(AND(D4="Congé",F4<>"Congé"),(AND(F4="Congé",D4<>"Congé"))),0.166666666666667,"")) | AC4: =IF(AND(D4="Congé sans solde",F4="Congé sans solde"),0.333333333333333,IF(OR(AND(D4="Congé sans solde",F4<>"Congé sans solde"),(AND(F4="Congé sans solde",D4<>"Congé sans solde"))),0.166666666666667,"")) | AD4: =IF(AND(D4="Congé spécial",F4="Congé spécial"),0.333333333333333,IF(OR(AND(D4="Congé spécial",F4<>"Congé décès"),(AND(F4="Congé spécial",D4<>"Congé spécial"))),0.166666666666667,"")) | AE4: =IF(AND(D4="Férié",F4="Férié"),0.333333333333333,IF(OR(AND(D4="Férié",F4<>"Férié"),(AND(F4="Férié",D4<>"Férié"))),0.166666666666667,""))
A5: =VLOOKUP(B5,Annuaire_roster!B:F,5,0) -> 0 | B5: BOULHROUD SALMA | C5: =IFERROR(IF(COUNTIFS(Pointage_brut!$E:$E,VLOOKUP($B5,Annuaire_roster!$B:$J,9,0),Pointage_brut!$A:$A,TEXT($Q5,"yyyymmdd")*1)=0,"",MOD(_xlfn.MINIFS(Pointage_brut!$F:$F,Pointage_brut!$E:$E,VLOOKUP($B5,Annuaire_roster!$B:$J,9,0),Pointage_brut!$A:$A,TEXT($Q5,"yyyymmdd")*1),1)),"") | D5: {=IFERROR(INDEX(Planning2[],MATCH(1,(Planning2[Nom]=B5)*(Planning2[Date]=Q5),0),3),"-")} -> 0.29166667 | E5: =IFERROR(IF(COUNTIFS(Pointage_brut!$E:$E,VLOOKUP($B5,Annuaire_roster!$B:$J,9,0),Pointage_brut!$A:$A,TEXT($Q5,"yyyymmdd")*1)=0,"",MOD(_xlfn.MAXIFS(Pointage_brut!$G:$G,Pointage_brut!$E:$E,VLOOKUP($B5,Annuaire_roster!$B:$J,9,0),Pointage_brut!$A:$A,TEXT($Q5,"yyyymmdd")*1),1)),"") | F5: {=IFERROR(INDEX(Planning2[],MATCH(1,(Planning2[Nom]=B5)*(Planning2[Date]=Q5),0),4),"-")} -> 0.70833333 | I5: =IF(IF(OR(C5="",D5="Congé",D5="OFF",D5="Congé spécial"),"",IF(D5>F5,D5-C5,IF(C5-D5<0,0,C5-D5)))<0.00068287037037037,"",IF(OR(D5="Congé",D5="OFF",C5="",D5="Congé spécial"),"",IF(D5>F5,D5-C5,IF(C5-D5<0,0,C5-D5)))) | K5: =IF(SUM(H5:J5)<0.00068287037037037,0,SUM(H5:J5)) -> 0 | L5: =IF(OR(F5="Congé",F5="OFF",M5="Abs",F5="Congé sans solde",F5="Férié",F5="Congé spécial",D5="Congé spécial"),0,IF(F5-E5<0,0,IF(F5-E5<=0.00068287037037037,0,F5-E5))) -> 0 | M5: =IF(AND(O5<>0,C5=""),"Abs",0) -> Abs | N5: =IFERROR(IF(OR(D5="OFF",D5="Congé",M5="Abs",D5="Congé sans solde",D5="Férié"),"",IF(O5-K5-L5>O5,O5,IF(O5-K5-L5<0,"",O5-K5-L5))),"") | O5: =IF(AG5="2H Pause déjeuner",IF(F5-D5-0.0833333333333333<0,F5-D5-0.0833333333333333+1,F5-D5-0.0833333333333333),IF(OR(AND(F5="OFF",D5="OFF"),AND(F5="Congé",D5="Congé"),AND(F5="Congé sans solde",D5="Congé sans solde"),AND(F5="Congé spécial",D5="Congé spécial"),AND(F5="Férié",D5="Férié"),AND(F5="OFF",D5="Congé"),AND(F5="OFF",D5="Congé sans solde"),AND(F5="OFF",D5="Congé spécial"),AND(F5="OFF",D5="Férié"),AND(F5="Congé",D5="OFF"),AND(F5="Congé",D5="Congé sans solde"),AND(F5="Congé",D5="Congé spécial"),AND(F5="Congé",D5="Férié"),AND(F5="Congé sans solde",D5="OFF"),AND(F5="Congé sans solde",D5="Congé"),AND(F5="Congé sans solde",D5="Congé spécial"),AND(F5="Congé sans solde",D5="Férié"),AND(F5="Congé spécial",D5="OFF"),AND(F5="Congé spécial",D5="Congé"),AND(F5="Congé spécial",D5="Congé sans solde"),AND(F5="Congé spécial",D5="Férié"),AND(F5="Férié",D5="OFF"),AND(F5="Férié",D5="Congé"),AND(F5="Férié",D5="Congé sans solde"),AND(F5="Férié",D5="Congé spécial")),0,IF(OR(F5="OFF",F5="Congé",F5="Congé spécial",F5="Congé sans solde",D5="OFF",D5="Congé",D5="Congé spécial",D5="Congé sans solde"),0.208333333333334,IF(AND(AG5="",F5-D5<0),("24:00:00"-D5)+("00:00:00"+F5)-0.0416666666666667,IF(AND(OR(AG5="Allaitement",AG5="Sans déjeuner"),F5-D5<0),("24:00:00"-D5)+("00:00:00"+F5),IF(AND(AG5="",F5-D5>0.166666666666667),F5-D5-0.0416666666666667,IF(AND(OR(AG5="Allaitement",AG5="Sans déjeuner"),F5-D5>0.166666666666667),F5-D5,F5-D5))))))) -> 0.375 | P5: =IFERROR(VLOOKUP($B5,Annuaire_roster!$B:$G,MATCH(P$1,Annuaire_roster!$B$1:$G$1,0),0),"-") -> Google Leads | Q5: 44717 | R5: =IF(M5="Abs",O5,0) -> 0.375 | S5: =SUM(R5,L5,I5,J5,W5,H5) -> 0.375 | T5: ="Sem - "&WEEKNUM(Q5,21) -> Sem - 23 | U5: =PROPER(TEXT(Q5,"mmmm")) -> June | V5: =+TEXT(Q5,"aaa") -> Sat | X5: =IFERROR(IF(M5="Abs",0,IF((D5-C5+E5-F5)<0.000694444444444444,0,(D5-C5+E5-F5))),0) -> 0 | Y5: =IFERROR(VLOOKUP(B5,Annuaire_roster!B:E,4,0),"-") -> 0 | Z5: =IFERROR(VLOOKUP(B5,Annuaire_roster!B:F,3,0),"-") -> Google Leads | AA5: =IFERROR(VLOOKUP(B5,Annuaire_roster!B:I,6,0),"-") -> 0 | AB5: =IF(AND(D5="Congé",F5="Congé"),0.333333333333333,IF(OR(AND(D5="Congé",F5<>"Congé"),(AND(F5="Congé",D5<>"Congé"))),0.166666666666667,"")) | AC5: =IF(AND(D5="Congé sans solde",F5="Congé sans solde"),0.333333333333333,IF(OR(AND(D5="Congé sans solde",F5<>"Congé sans solde"),(AND(F5="Congé sans solde",D5<>"Congé sans solde"))),0.166666666666667,"")) | AD5: =IF(AND(D5="Congé spécial",F5="Congé spécial"),0.333333333333333,IF(OR(AND(D5="Congé spécial",F5<>"Congé décès"),(AND(F5="Congé spécial",D5<>"Congé spécial"))),0.166666666666667,"")) | AE5: =IF(AND(D5="Férié",F5="Férié"),0.333333333333333,IF(OR(AND(D5="Férié",F5<>"Férié"),(AND(F5="Férié",D5<>"Férié"))),0.166666666666667,""))
A6: =VLOOKUP(B6,Annuaire_roster!B:F,5,0) -> 0 | B6: NEMMAOUI MOUNIRA | C6: =IFERROR(IF(COUNTIFS(Pointage_brut!$E:$E,VLOOKUP($B6,Annuaire_roster!$B:$J,9,0),Pointage_brut!$A:$A,TEXT($Q6,"yyyymmdd")*1)=0,"",MOD(_xlfn.MINIFS(Pointage_brut!$F:$F,Pointage_brut!$E:$E,VLOOKUP($B6,Annuaire_roster!$B:$J,9,0),Pointage_brut!$A:$A,TEXT($Q6,"yyyymmdd")*1),1)),"") | D6: {=IFERROR(INDEX(Planning2[],MATCH(1,(Planning2[Nom]=B6)*(Planning2[Date]=Q6),0),3),"-")} -> 0.29166667 | E6: =IFERROR(IF(COUNTIFS(Pointage_brut!$E:$E,VLOOKUP($B6,Annuaire_roster!$B:$J,9,0),Pointage_brut!$A:$A,TEXT($Q6,"yyyymmdd")*1)=0,"",MOD(_xlfn.MAXIFS(Pointage_brut!$G:$G,Pointage_brut!$E:$E,VLOOKUP($B6,Annuaire_roster!$B:$J,9,0),Pointage_brut!$A:$A,TEXT($Q6,"yyyymmdd")*1),1)),"") | F6: {=IFERROR(INDEX(Planning2[],MATCH(1,(Planning2[Nom]=B6)*(Planning2[Date]=Q6),0),4),"-")} -> 0.70833333 | I6: =IF(IF(OR(C6="",D6="Congé",D6="OFF",D6="Congé spécial"),"",IF(D6>F6,D6-C6,IF(C6-D6<0,0,C6-D6)))<0.00068287037037037,"",IF(OR(D6="Congé",D6="OFF",C6="",D6="Congé spécial"),"",IF(D6>F6,D6-C6,IF(C6-D6<0,0,C6-D6)))) | K6: =IF(SUM(H6:J6)<0.00068287037037037,0,SUM(H6:J6)) -> 0 | L6: =IF(OR(F6="Congé",F6="OFF",M6="Abs",F6="Congé sans solde",F6="Férié",F6="Congé spécial",D6="Congé spécial"),0,IF(F6-E6<0,0,IF(F6-E6<=0.00068287037037037,0,F6-E6))) -> 0 | M6: =IF(AND(O6<>0,C6=""),"Abs",0) -> Abs | N6: =IFERROR(IF(OR(D6="OFF",D6="Congé",M6="Abs",D6="Congé sans solde",D6="Férié"),"",IF(O6-K6-L6>O6,O6,IF(O6-K6-L6<0,"",O6-K6-L6))),"") | O6: =IF(AG6="2H Pause déjeuner",IF(F6-D6-0.0833333333333333<0,F6-D6-0.0833333333333333+1,F6-D6-0.0833333333333333),IF(OR(AND(F6="OFF",D6="OFF"),AND(F6="Congé",D6="Congé"),AND(F6="Congé sans solde",D6="Congé sans solde"),AND(F6="Congé spécial",D6="Congé spécial"),AND(F6="Férié",D6="Férié"),AND(F6="OFF",D6="Congé"),AND(F6="OFF",D6="Congé sans solde"),AND(F6="OFF",D6="Congé spécial"),AND(F6="OFF",D6="Férié"),AND(F6="Congé",D6="OFF"),AND(F6="Congé",D6="Congé sans solde"),AND(F6="Congé",D6="Congé spécial"),AND(F6="Congé",D6="Férié"),AND(F6="Congé sans solde",D6="OFF"),AND(F6="Congé sans solde",D6="Congé"),AND(F6="Congé sans solde",D6="Congé spécial"),AND(F6="Congé sans solde",D6="Férié"),AND(F6="Congé spécial",D6="OFF"),AND(F6="Congé spécial",D6="Congé"),AND(F6="Congé spécial",D6="Congé sans solde"),AND(F6="Congé spécial",D6="Férié"),AND(F6="Férié",D6="OFF"),AND(F6="Férié",D6="Congé"),AND(F6="Férié",D6="Congé sans solde"),AND(F6="Férié",D6="Congé spécial")),0,IF(OR(F6="OFF",F6="Congé",F6="Congé spécial",F6="Congé sans solde",D6="OFF",D6="Congé",D6="Congé spécial",D6="Congé sans solde"),0.208333333333334,IF(AND(AG6="",F6-D6<0),("24:00:00"-D6)+("00:00:00"+F6)-0.0416666666666667,IF(AND(OR(AG6="Allaitement",AG6="Sans déjeuner"),F6-D6<0),("24:00:00"-D6)+("00:00:00"+F6),IF(AND(AG6="",F6-D6>0.166666666666667),F6-D6-0.0416666666666667,IF(AND(OR(AG6="Allaitement",AG6="Sans déjeuner"),F6-D6>0.166666666666667),F6-D6,F6-D6))))))) -> 0.375 | P6: =IFERROR(VLOOKUP($B6,Annuaire_roster!$B:$G,MATCH(P$1,Annuaire_roster!$B$1:$G$1,0),0),"-") -> Google Leads | Q6: 44717 | R6: =IF(M6="Abs",O6,0) -> 0.375 | S6: =SUM(R6,L6,I6,J6,W6,H6) -> 0.375 | T6: ="Sem - "&WEEKNUM(Q6,21) -> Sem - 23 | U6: =PROPER(TEXT(Q6,"mmmm")) -> June | V6: =+TEXT(Q6,"aaa") -> Sat | X6: =IFERROR(IF(M6="Abs",0,IF((D6-C6+E6-F6)<0.000694444444444444,0,(D6-C6+E6-F6))),0) -> 0 | Y6: =IFERROR(VLOOKUP(B6,Annuaire_roster!B:E,4,0),"-") -> 0 | Z6: =IFERROR(VLOOKUP(B6,Annuaire_roster!B:F,3,0),"-") -> Google Leads | AA6: =IFERROR(VLOOKUP(B6,Annuaire_roster!B:I,6,0),"-") -> 0 | AB6: =IF(AND(D6="Congé",F6="Congé"),0.333333333333333,IF(OR(AND(D6="Congé",F6<>"Congé"),(AND(F6="Congé",D6<>"Congé"))),0.166666666666667,"")) | AC6: =IF(AND(D6="Congé sans solde",F6="Congé sans solde"),0.333333333333333,IF(OR(AND(D6="Congé sans solde",F6<>"Congé sans solde"),(AND(F6="Congé sans solde",D6<>"Congé sans solde"))),0.166666666666667,"")) | AD6: =IF(AND(D6="Congé spécial",F6="Congé spécial"),0.333333333333333,IF(OR(AND(D6="Congé spécial",F6<>"Congé décès"),(AND(F6="Congé spécial",D6<>"Congé spécial"))),0.166666666666667,"")) | AE6: =IF(AND(D6="Férié",F6="Férié"),0.333333333333333,IF(OR(AND(D6="Férié",F6<>"Férié"),(AND(F6="Férié",D6<>"Férié"))),0.166666666666667,""))
A7: =VLOOKUP(B7,Annuaire_roster!B:F,5,0) -> 669 | B7: NIANG NDEYE ABSA | C7: =IFERROR(IF(COUNTIFS(Pointage_brut!$E:$E,VLOOKUP($B7,Annuaire_roster!$B:$J,9,0),Pointage_brut!$A:$A,TEXT($Q7,"yyyymmdd")*1)=0,"",MOD(_xlfn.MINIFS(Pointage_brut!$F:$F,Pointage_brut!$E:$E,VLOOKUP($B7,Annuaire_roster!$B:$J,9,0),Pointage_brut!$A:$A,TEXT($Q7,"yyyymmdd")*1),1)),"") | D7: {=IFERROR(INDEX(Planning2[],MATCH(1,(Planning2[Nom]=B7)*(Planning2[Date]=Q7),0),3),"-")} -> 0.29166667 | E7: =IFERROR(IF(COUNTIFS(Pointage_brut!$E:$E,VLOOKUP($B7,Annuaire_roster!$B:$J,9,0),Pointage_brut!$A:$A,TEXT($Q7,"yyyymmdd")*1)=0,"",MOD(_xlfn.MAXIFS(Pointage_brut!$G:$G,Pointage_brut!$E:$E,VLOOKUP($B7,Annuaire_roster!$B:$J,9,0),Pointage_brut!$A:$A,TEXT($Q7,"yyyymmdd")*1),1)),"") | F7: {=IFERROR(INDEX(Planning2[],MATCH(1,(Planning2[Nom]=B7)*(Planning2[Date]=Q7),0),4),"-")} -> 0.70833333 | I7: =IF(IF(OR(C7="",D7="Congé",D7="OFF",D7="Congé spécial"),"",IF(D7>F7,D7-C7,IF(C7-D7<0,0,C7-D7)))<0.00068287037037037,"",IF(OR(D7="Congé",D7="OFF",C7="",D7="Congé spécial"),"",IF(D7>F7,D7-C7,IF(C7-D7<0,0,C7-D7)))) | K7: =IF(SUM(H7:J7)<0.00068287037037037,0,SUM(H7:J7)) -> 0 | L7: =IF(OR(F7="Congé",F7="OFF",M7="Abs",F7="Congé sans solde",F7="Férié",F7="Congé spécial",D7="Congé spécial"),0,IF(F7-E7<0,0,IF(F7-E7<=0.00068287037037037,0,F7-E7))) -> 0 | M7: =IF(AND(O7<>0,C7=""),"Abs",0) -> Abs | N7: =IFERROR(IF(OR(D7="OFF",D7="Congé",M7="Abs",D7="Congé sans solde",D7="Férié"),"",IF(O7-K7-L7>O7,O7,IF(O7-K7-L7<0,"",O7-K7-L7))),"") | O7: =IF(AG7="2H Pause déjeuner",IF(F7-D7-0.0833333333333333<0,F7-D7-0.0833333333333333+1,F7-D7-0.0833333333333333),IF(OR(AND(F7="OFF",D7="OFF"),AND(F7="Congé",D7="Congé"),AND(F7="Congé sans solde",D7="Congé sans solde"),AND(F7="Congé spécial",D7="Congé spécial"),AND(F7="Férié",D7="Férié"),AND(F7="OFF",D7="Congé"),AND(F7="OFF",D7="Congé sans solde"),AND(F7="OFF",D7="Congé spécial"),AND(F7="OFF",D7="Férié"),AND(F7="Congé",D7="OFF"),AND(F7="Congé",D7="Congé sans solde"),AND(F7="Congé",D7="Congé spécial"),AND(F7="Congé",D7="Férié"),AND(F7="Congé sans solde",D7="OFF"),AND(F7="Congé sans solde",D7="Congé"),AND(F7="Congé sans solde",D7="Congé spécial"),AND(F7="Congé sans solde",D7="Férié"),AND(F7="Congé spécial",D7="OFF"),AND(F7="Congé spécial",D7="Congé"),AND(F7="Congé spécial",D7="Congé sans solde"),AND(F7="Congé spécial",D7="Férié"),AND(F7="Férié",D7="OFF"),AND(F7="Férié",D7="Congé"),AND(F7="Férié",D7="Congé sans solde"),AND(F7="Férié",D7="Congé spécial")),0,IF(OR(F7="OFF",F7="Congé",F7="Congé spécial",F7="Congé sans solde",D7="OFF",D7="Congé",D7="Congé spécial",D7="Congé sans solde"),0.208333333333334,IF(AND(AG7="",F7-D7<0),("24:00:00"-D7)+("00:00:00"+F7)-0.0416666666666667,IF(AND(OR(AG7="Allaitement",AG7="Sans déjeuner"),F7-D7<0),("24:00:00"-D7)+("00:00:00"+F7),IF(AND(AG7="",F7-D7>0.166666666666667),F7-D7-0.0416666666666667,IF(AND(OR(AG7="Allaitement",AG7="Sans déjeuner"),F7-D7>0.166666666666667),F7-D7,F7-D7))))))) -> 0.375 | P7: =IFERROR(VLOOKUP($B7,Annuaire_roster!$B:$G,MATCH(P$1,Annuaire_roster!$B$1:$G$1,0),0),"-") -> Google Leads | Q7: 44717 | R7: =IF(M7="Abs",O7,0) -> 0.375 | S7: =SUM(R7,L7,I7,J7,W7,H7) -> 0.375 | T7: ="Sem - "&WEEKNUM(Q7,21) -> Sem - 23 | U7: =PROPER(TEXT(Q7,"mmmm")) -> June | V7: =+TEXT(Q7,"aaa") -> Sat | X7: =IFERROR(IF(M7="Abs",0,IF((D7-C7+E7-F7)<0.000694444444444444,0,(D7-C7+E7-F7))),0) -> 0 | Y7: =IFERROR(VLOOKUP(B7,Annuaire_roster!B:E,4,0),"-") -> CHOUIFI Mustapha | Z7: =IFERROR(VLOOKUP(B7,Annuaire_roster!B:F,3,0),"-") -> Google Leads | AA7: =IFERROR(VLOOKUP(B7,Annuaire_roster!B:I,6,0),"-") -> Forfaitaire | AB7: =IF(AND(D7="Congé",F7="Congé"),0.333333333333333,IF(OR(AND(D7="Congé",F7<>"Congé"),(AND(F7="Congé",D7<>"Congé"))),0.166666666666667,"")) | AC7: =IF(AND(D7="Congé sans solde",F7="Congé sans solde"),0.333333333333333,IF(OR(AND(D7="Congé sans solde",F7<>"Congé sans solde"),(AND(F7="Congé sans solde",D7<>"Congé sans solde"))),0.166666666666667,"")) | AD7: =IF(AND(D7="Congé spécial",F7="Congé spécial"),0.333333333333333,IF(OR(AND(D7="Congé spécial",F7<>"Congé décès"),(AND(F7="Congé spécial",D7<>"Congé spécial"))),0.166666666666667,"")) | AE7: =IF(AND(D7="Férié",F7="Férié"),0.333333333333333,IF(OR(AND(D7="Férié",F7<>"Férié"),(AND(F7="Férié",D7<>"Férié"))),0.166666666666667,""))
A8: =VLOOKUP(B8,Annuaire_roster!B:F,5,0) -> 0 | B8: BENSAR ANAS | C8: =IFERROR(IF(COUNTIFS(Pointage_brut!$E:$E,VLOOKUP($B8,Annuaire_roster!$B:$J,9,0),Pointage_brut!$A:$A,TEXT($Q8,"yyyymmdd")*1)=0,"",MOD(_xlfn.MINIFS(Pointage_brut!$F:$F,Pointage_brut!$E:$E,VLOOKUP($B8,Annuaire_roster!$B:$J,9,0),Pointage_brut!$A:$A,TEXT($Q8,"yyyymmdd")*1),1)),"") | D8: {=IFERROR(INDEX(Planning2[],MATCH(1,(Planning2[Nom]=B8)*(Planning2[Date]=Q8),0),3),"-")} -> 0.29166667 | E8: =IFERROR(IF(COUNTIFS(Pointage_brut!$E:$E,VLOOKUP($B8,Annuaire_roster!$B:$J,9,0),Pointage_brut!$A:$A,TEXT($Q8,"yyyymmdd")*1)=0,"",MOD(_xlfn.MAXIFS(Pointage_brut!$G:$G,Pointage_brut!$E:$E,VLOOKUP($B8,Annuaire_roster!$B:$J,9,0),Pointage_brut!$A:$A,TEXT($Q8,"yyyymmdd")*1),1)),"") | F8: {=IFERROR(INDEX(Planning2[],MATCH(1,(Planning2[Nom]=B8)*(Planning2[Date]=Q8),0),4),"-")} -> 0.70833333 | I8: =IF(IF(OR(C8="",D8="Congé",D8="OFF",D8="Congé spécial"),"",IF(D8>F8,D8-C8,IF(C8-D8<0,0,C8-D8)))<0.00068287037037037,"",IF(OR(D8="Congé",D8="OFF",C8="",D8="Congé spécial"),"",IF(D8>F8,D8-C8,IF(C8-D8<0,0,C8-D8)))) | K8: =IF(SUM(H8:J8)<0.00068287037037037,0,SUM(H8:J8)) -> 0 | L8: =IF(OR(F8="Congé",F8="OFF",M8="Abs",F8="Congé sans solde",F8="Férié",F8="Congé spécial",D8="Congé spécial"),0,IF(F8-E8<0,0,IF(F8-E8<=0.00068287037037037,0,F8-E8))) -> 0 | M8: =IF(AND(O8<>0,C8=""),"Abs",0) -> Abs | N8: =IFERROR(IF(OR(D8="OFF",D8="Congé",M8="Abs",D8="Congé sans solde",D8="Férié"),"",IF(O8-K8-L8>O8,O8,IF(O8-K8-L8<0,"",O8-K8-L8))),"") | O8: =IF(AG8="2H Pause déjeuner",IF(F8-D8-0.0833333333333333<0,F8-D8-0.0833333333333333+1,F8-D8-0.0833333333333333),IF(OR(AND(F8="OFF",D8="OFF"),AND(F8="Congé",D8="Congé"),AND(F8="Congé sans solde",D8="Congé sans solde"),AND(F8="Congé spécial",D8="Congé spécial"),AND(F8="Férié",D8="Férié"),AND(F8="OFF",D8="Congé"),AND(F8="OFF",D8="Congé sans solde"),AND(F8="OFF",D8="Congé spécial"),AND(F8="OFF",D8="Férié"),AND(F8="Congé",D8="OFF"),AND(F8="Congé",D8="Congé sans solde"),AND(F8="Congé",D8="Congé spécial"),AND(F8="Congé",D8="Férié"),AND(F8="Congé sans solde",D8="OFF"),AND(F8="Congé sans solde",D8="Congé"),AND(F8="Congé sans solde",D8="Congé spécial"),AND(F8="Congé sans solde",D8="Férié"),AND(F8="Congé spécial",D8="OFF"),AND(F8="Congé spécial",D8="Congé"),AND(F8="Congé spécial",D8="Congé sans solde"),AND(F8="Congé spécial",D8="Férié"),AND(F8="Férié",D8="OFF"),AND(F8="Férié",D8="Congé"),AND(F8="Férié",D8="Congé sans solde"),AND(F8="Férié",D8="Congé spécial")),0,IF(OR(F8="OFF",F8="Congé",F8="Congé spécial",F8="Congé sans solde",D8="OFF",D8="Congé",D8="Congé spécial",D8="Congé sans solde"),0.208333333333334,IF(AND(AG8="",F8-D8<0),("24:00:00"-D8)+("00:00:00"+F8)-0.0416666666666667,IF(AND(OR(AG8="Allaitement",AG8="Sans déjeuner"),F8-D8<0),("24:00:00"-D8)+("00:00:00"+F8),IF(AND(AG8="",F8-D8>0.166666666666667),F8-D8-0.0416666666666667,IF(AND(OR(AG8="Allaitement",AG8="Sans déjeuner"),F8-D8>0.166666666666667),F8-D8,F8-D8))))))) -> 0.375 | P8: =IFERROR(VLOOKUP($B8,Annuaire_roster!$B:$G,MATCH(P$1,Annuaire_roster!$B$1:$G$1,0),0),"-") -> Google Leads | Q8: 44717 | R8: =IF(M8="Abs",O8,0) -> 0.375 | S8: =SUM(R8,L8,I8,J8,W8,H8) -> 0.375 | T8: ="Sem - "&WEEKNUM(Q8,21) -> Sem - 23 | U8: =PROPER(TEXT(Q8,"mmmm")) -> June | V8: =+TEXT(Q8,"aaa") -> Sat | X8: =IFERROR(IF(M8="Abs",0,IF((D8-C8+E8-F8)<0.000694444444444444,0,(D8-C8+E8-F8))),0) -> 0 | Y8: =IFERROR(VLOOKUP(B8,Annuaire_roster!B:E,4,0),"-") -> 0 | Z8: =IFERROR(VLOOKUP(B8,Annuaire_roster!B:F,3,0),"-") -> Google Leads | AA8: =IFERROR(VLOOKUP(B8,Annuaire_roster!B:I,6,0),"-") -> 0 | AB8: =IF(AND(D8="Congé",F8="Congé"),0.333333333333333,IF(OR(AND(D8="Congé",F8<>"Congé"),(AND(F8="Congé",D8<>"Congé"))),0.166666666666667,"")) | AC8: =IF(AND(D8="Congé sans solde",F8="Congé sans solde"),0.333333333333333,IF(OR(AND(D8="Congé sans solde",F8<>"Congé sans solde"),(AND(F8="Congé sans solde",D8<>"Congé sans solde"))),0.166666666666667,"")) | AD8: =IF(AND(D8="Congé spécial",F8="Congé spécial"),0.333333333333333,IF(OR(AND(D8="Congé spécial",F8<>"Congé décès"),(AND(F8="Congé spécial",D8<>"Congé spécial"))),0.166666666666667,"")) | AE8: =IF(AND(D8="Férié",F8="Férié"),0.333333333333333,IF(OR(AND(D8="Férié",F8<>"Férié"),(AND(F8="Férié",D8<>"Férié"))),0.166666666666667,""))
A9: =VLOOKUP(B9,Annuaire_roster!B:F,5,0) -> 1165 | B9: MELLAHI YOUSSEF | C9: =IFERROR(IF(COUNTIFS(Pointage_brut!$E:$E,VLOOKUP($B9,Annuaire_roster!$B:$J,9,0),Pointage_brut!$A:$A,TEXT($Q9,"yyyymmdd")*1)=0,"",MOD(_xlfn.MINIFS(Pointage_brut!$F:$F,Pointage_brut!$E:$E,VLOOKUP($B9,Annuaire_roster!$B:$J,9,0),Pointage_brut!$A:$A,TEXT($Q9,"yyyymmdd")*1),1)),"") | D9: {=IFERROR(INDEX(Planning2[],MATCH(1,(Planning2[Nom]=B9)*(Planning2[Date]=Q9),0),3),"-")} -> 0.29166667 | E9: =IFERROR(IF(COUNTIFS(Pointage_brut!$E:$E,VLOOKUP($B9,Annuaire_roster!$B:$J,9,0),Pointage_brut!$A:$A,TEXT($Q9,"yyyymmdd")*1)=0,"",MOD(_xlfn.MAXIFS(Pointage_brut!$G:$G,Pointage_brut!$E:$E,VLOOKUP($B9,Annuaire_roster!$B:$J,9,0),Pointage_brut!$A:$A,TEXT($Q9,"yyyymmdd")*1),1)),"") | F9: {=IFERROR(INDEX(Planning2[],MATCH(1,(Planning2[Nom]=B9)*(Planning2[Date]=Q9),0),4),"-")} -> 0.70833333 | I9: =IF(IF(OR(C9="",D9="Congé",D9="OFF",D9="Congé spécial"),"",IF(D9>F9,D9-C9,IF(C9-D9<0,0,C9-D9)))<0.00068287037037037,"",IF(OR(D9="Congé",D9="OFF",C9="",D9="Congé spécial"),"",IF(D9>F9,D9-C9,IF(C9-D9<0,0,C9-D9)))) | K9: =IF(SUM(H9:J9)<0.00068287037037037,0,SUM(H9:J9)) -> 0 | L9: =IF(OR(F9="Congé",F9="OFF",M9="Abs",F9="Congé sans solde",F9="Férié",F9="Congé spécial",D9="Congé spécial"),0,IF(F9-E9<0,0,IF(F9-E9<=0.00068287037037037,0,F9-E9))) -> 0 | M9: =IF(AND(O9<>0,C9=""),"Abs",0) -> Abs | N9: =IFERROR(IF(OR(D9="OFF",D9="Congé",M9="Abs",D9="Congé sans solde",D9="Férié"),"",IF(O9-K9-L9>O9,O9,IF(O9-K9-L9<0,"",O9-K9-L9))),"") | O9: =IF(AG9="2H Pause déjeuner",IF(F9-D9-0.0833333333333333<0,F9-D9-0.0833333333333333+1,F9-D9-0.0833333333333333),IF(OR(AND(F9="OFF",D9="OFF"),AND(F9="Congé",D9="Congé"),AND(F9="Congé sans solde",D9="Congé sans solde"),AND(F9="Congé spécial",D9="Congé spécial"),AND(F9="Férié",D9="Férié"),AND(F9="OFF",D9="Congé"),AND(F9="OFF",D9="Congé sans solde"),AND(F9="OFF",D9="Congé spécial"),AND(F9="OFF",D9="Férié"),AND(F9="Congé",D9="OFF"),AND(F9="Congé",D9="Congé sans solde"),AND(F9="Congé",D9="Congé spécial"),AND(F9="Congé",D9="Férié"),AND(F9="Congé sans solde",D9="OFF"),AND(F9="Congé sans solde",D9="Congé"),AND(F9="Congé sans solde",D9="Congé spécial"),AND(F9="Congé sans solde",D9="Férié"),AND(F9="Congé spécial",D9="OFF"),AND(F9="Congé spécial",D9="Congé"),AND(F9="Congé spécial",D9="Congé sans solde"),AND(F9="Congé spécial",D9="Férié"),AND(F9="Férié",D9="OFF"),AND(F9="Férié",D9="Congé"),AND(F9="Férié",D9="Congé sans solde"),AND(F9="Férié",D9="Congé spécial")),0,IF(OR(F9="OFF",F9="Congé",F9="Congé spécial",F9="Congé sans solde",D9="OFF",D9="Congé",D9="Congé spécial",D9="Congé sans solde"),0.208333333333334,IF(AND(AG9="",F9-D9<0),("24:00:00"-D9)+("00:00:00"+F9)-0.0416666666666667,IF(AND(OR(AG9="Allaitement",AG9="Sans déjeuner"),F9-D9<0),("24:00:00"-D9)+("00:00:00"+F9),IF(AND(AG9="",F9-D9>0.166666666666667),F9-D9-0.0416666666666667,IF(AND(OR(AG9="Allaitement",AG9="Sans déjeuner"),F9-D9>0.166666666666667),F9-D9,F9-D9))))))) -> 0.375 | P9: =IFERROR(VLOOKUP($B9,Annuaire_roster!$B:$G,MATCH(P$1,Annuaire_roster!$B$1:$G$1,0),0),"-") -> Google Leads | Q9: 44717 | R9: =IF(M9="Abs",O9,0) -> 0.375 | S9: =SUM(R9,L9,I9,J9,W9,H9) -> 0.375 | T9: ="Sem - "&WEEKNUM(Q9,21) -> Sem - 23 | U9: =PROPER(TEXT(Q9,"mmmm")) -> June | V9: =+TEXT(Q9,"aaa") -> Sat | X9: =IFERROR(IF(M9="Abs",0,IF((D9-C9+E9-F9)<0.000694444444444444,0,(D9-C9+E9-F9))),0) -> 0 | Y9: =IFERROR(VLOOKUP(B9,Annuaire_roster!B:E,4,0),"-") -> OUAQERROUCH Nour-El Houda | Z9: =IFERROR(VLOOKUP(B9,Annuaire_roster!B:F,3,0),"-") -> Google Leads | AA9: =IFERROR(VLOOKUP(B9,Annuaire_roster!B:I,6,0),"-") -> Forfaitaire | AB9: =IF(AND(D9="Congé",F9="Congé"),0.333333333333333,IF(OR(AND(D9="Congé",F9<>"Congé"),(AND(F9="Congé",D9<>"Congé"))),0.166666666666667,"")) | AC9: =IF(AND(D9="Congé sans solde",F9="Congé sans solde"),0.333333333333333,IF(OR(AND(D9="Congé sans solde",F9<>"Congé sans solde"),(AND(F9="Congé sans solde",D9<>"Congé sans solde"))),0.166666666666667,"")) | AD9: =IF(AND(D9="Congé spécial",F9="Congé spécial"),0.333333333333333,IF(OR(AND(D9="Congé spécial",F9<>"Congé décès"),(AND(F9="Congé spécial",D9<>"Congé spécial"))),0.166666666666667,"")) | AE9: =IF(AND(D9="Férié",F9="Férié"),0.333333333333333,IF(OR(AND(D9="Férié",F9<>"Férié"),(AND(F9="Férié",D9<>"Férié"))),0.166666666666667,""))
A10: =VLOOKUP(B10,Annuaire_roster!B:F,5,0) -> 0 | B10: EL HOUJJAJI Soufiane | C10: =IFERROR(IF(COUNTIFS(Pointage_brut!$E:$E,VLOOKUP($B10,Annuaire_roster!$B:$J,9,0),Pointage_brut!$A:$A,TEXT($Q10,"yyyymmdd")*1)=0,"",MOD(_xlfn.MINIFS(Pointage_brut!$F:$F,Pointage_brut!$E:$E,VLOOKUP($B10,Annuaire_roster!$B:$J,9,0),Pointage_brut!$A:$A,TEXT($Q10,"yyyymmdd")*1),1)),"") | D10: {=IFERROR(INDEX(Planning2[],MATCH(1,(Planning2[Nom]=B10)*(Planning2[Date]=Q10),0),3),"-")} -> 0.29166667 | E10: =IFERROR(IF(COUNTIFS(Pointage_brut!$E:$E,VLOOKUP($B10,Annuaire_roster!$B:$J,9,0),Pointage_brut!$A:$A,TEXT($Q10,"yyyymmdd")*1)=0,"",MOD(_xlfn.MAXIFS(Pointage_brut!$G:$G,Pointage_brut!$E:$E,VLOOKUP($B10,Annuaire_roster!$B:$J,9,0),Pointage_brut!$A:$A,TEXT($Q10,"yyyymmdd")*1),1)),"") | F10: {=IFERROR(INDEX(Planning2[],MATCH(1,(Planning2[Nom]=B10)*(Planning2[Date]=Q10),0),4),"-")} -> 0.70833333 | I10: =IF(IF(OR(C10="",D10="Congé",D10="OFF",D10="Congé spécial"),"",IF(D10>F10,D10-C10,IF(C10-D10<0,0,C10-D10)))<0.00068287037037037,"",IF(OR(D10="Congé",D10="OFF",C10="",D10="Congé spécial"),"",IF(D10>F10,D10-C10,IF(C10-D10<0,0,C10-D10)))) | K10: =IF(SUM(H10:J10)<0.00068287037037037,0,SUM(H10:J10)) -> 0 | L10: =IF(OR(F10="Congé",F10="OFF",M10="Abs",F10="Congé sans solde",F10="Férié",F10="Congé spécial",D10="Congé spécial"),0,IF(F10-E10<0,0,IF(F10-E10<=0.00068287037037037,0,F10-E10))) -> 0 | M10: =IF(AND(O10<>0,C10=""),"Abs",0) -> Abs | N10: =IFERROR(IF(OR(D10="OFF",D10="Congé",M10="Abs",D10="Congé sans solde",D10="Férié"),"",IF(O10-K10-L10>O10,O10,IF(O10-K10-L10<0,"",O10-K10-L10))),"") | O10: =IF(AG10="2H Pause déjeuner",IF(F10-D10-0.0833333333333333<0,F10-D10-0.0833333333333333+1,F10-D10-0.0833333333333333),IF(OR(AND(F10="OFF",D10="OFF"),AND(F10="Congé",D10="Congé"),AND(F10="Congé sans solde",D10="Congé sans solde"),AND(F10="Congé spécial",D10="Congé spécial"),AND(F10="Férié",D10="Férié"),AND(F10="OFF",D10="Congé"),AND(F10="OFF",D10="Congé sans solde"),AND(F10="OFF",D10="Congé spécial"),AND(F10="OFF",D10="Férié"),AND(F10="Congé",D10="OFF"),AND(F10="Congé",D10="Congé sans solde"),AND(F10="Congé",D10="Congé spécial"),AND(F10="Congé",D10="Férié"),AND(F10="Congé sans solde",D10="OFF"),AND(F10="Congé sans solde",D10="Congé"),AND(F10="Congé sans solde",D10="Congé spécial"),AND(F10="Congé sans solde",D10="Férié"),AND(F10="Congé spécial",D10="OFF"),AND(F10="Congé spécial",D10="Congé"),AND(F10="Congé spécial",D10="Congé sans solde"),AND(F10="Congé spécial",D10="Férié"),AND(F10="Férié",D10="OFF"),AND(F10="Férié",D10="Congé"),AND(F10="Férié",D10="Congé sans solde"),AND(F10="Férié",D10="Congé spécial")),0,IF(OR(F10="OFF",F10="Congé",F10="Congé spécial",F10="Congé sans solde",D10="OFF",D10="Congé",D10="Congé spécial",D10="Congé sans solde"),0.208333333333334,IF(AND(AG10="",F10-D10<0),("24:00:00"-D10)+("00:00:00"+F10)-0.0416666666666667,IF(AND(OR(AG10="Allaitement",AG10="Sans déjeuner"),F10-D10<0),("24:00:00"-D10)+("00:00:00"+F10),IF(AND(AG10="",F10-D10>0.166666666666667),F10-D10-0.0416666666666667,IF(AND(OR(AG10="Allaitement",AG10="Sans déjeuner"),F10-D10>0.166666666666667),F10-D10,F10-D10))))))) -> 0.375 | P10: =IFERROR(VLOOKUP($B10,Annuaire_roster!$B:$G,MATCH(P$1,Annuaire_roster!$B$1:$G$1,0),0),"-") -> Google Leads | Q10: 44717 | R10: =IF(M10="Abs",O10,0) -> 0.375 | S10: =SUM(R10,L10,I10,J10,W10,H10) -> 0.375 | T10: ="Sem - "&WEEKNUM(Q10,21) -> Sem - 23 | U10: =PROPER(TEXT(Q10,"mmmm")) -> June | V10: =+TEXT(Q10,"aaa") -> Sat | X10: =IFERROR(IF(M10="Abs",0,IF((D10-C10+E10-F10)<0.000694444444444444,0,(D10-C10+E10-F10))),0) -> 0 | Y10: =IFERROR(VLOOKUP(B10,Annuaire_roster!B:E,4,0),"-") -> CHOUIFI Mustapha | Z10: =IFERROR(VLOOKUP(B10,Annuaire_roster!B:F,3,0),"-") -> Google Leads | AA10: =IFERROR(VLOOKUP(B10,Annuaire_roster!B:I,6,0),"-") -> Forfaitaire | AB10: =IF(AND(D10="Congé",F10="Congé"),0.333333333333333,IF(OR(AND(D10="Congé",F10<>"Congé"),(AND(F10="Congé",D10<>"Congé"))),0.166666666666667,"")) | AC10: =IF(AND(D10="Congé sans solde",F10="Congé sans solde"),0.333333333333333,IF(OR(AND(D10="Congé sans solde",F10<>"Congé sans solde"),(AND(F10="Congé sans solde",D10<>"Congé sans solde"))),0.166666666666667,"")) | AD10: =IF(AND(D10="Congé spécial",F10="Congé spécial"),0.333333333333333,IF(OR(AND(D10="Congé spécial",F10<>"Congé décès"),(AND(F10="Congé spécial",D10<>"Congé spécial"))),0.166666666666667,"")) | AE10: =IF(AND(D10="Férié",F10="Férié"),0.333333333333333,IF(OR(AND(D10="Férié",F10<>"Férié"),(AND(F10="Férié",D10<>"Férié"))),0.166666666666667,""))
A11: =VLOOKUP(B11,Annuaire_roster!B:F,5,0) -> 0 | B11: BOURABAA HASSAN | C11: =IFERROR(IF(COUNTIFS(Pointage_brut!$E:$E,VLOOKUP($B11,Annuaire_roster!$B:$J,9,0),Pointage_brut!$A:$A,TEXT($Q11,"yyyymmdd")*1)=0,"",MOD(_xlfn.MINIFS(Pointage_brut!$F:$F,Pointage_brut!$E:$E,VLOOKUP($B11,Annuaire_roster!$B:$J,9,0),Pointage_brut!$A:$A,TEXT($Q11,"yyyymmdd")*1),1)),"") | D11: {=IFERROR(INDEX(Planning2[],MATCH(1,(Planning2[Nom]=B11)*(Planning2[Date]=Q11),0),3),"-")} -> 0.29166667 | E11: =IFERROR(IF(COUNTIFS(Pointage_brut!$E:$E,VLOOKUP($B11,Annuaire_roster!$B:$J,9,0),Pointage_brut!$A:$A,TEXT($Q11,"yyyymmdd")*1)=0,"",MOD(_xlfn.MAXIFS(Pointage_brut!$G:$G,Pointage_brut!$E:$E,VLOOKUP($B11,Annuaire_roster!$B:$J,9,0),Pointage_brut!$A:$A,TEXT($Q11,"yyyymmdd")*1),1)),"") | F11: {=IFERROR(INDEX(Planning2[],MATCH(1,(Planning2[Nom]=B11)*(Planning2[Date]=Q11),0),4),"-")} -> 0.70833333 | I11: =IF(IF(OR(C11="",D11="Congé",D11="OFF",D11="Congé spécial"),"",IF(D11>F11,D11-C11,IF(C11-D11<0,0,C11-D11)))<0.00068287037037037,"",IF(OR(D11="Congé",D11="OFF",C11="",D11="Congé spécial"),"",IF(D11>F11,D11-C11,IF(C11-D11<0,0,C11-D11)))) | K11: =IF(SUM(H11:J11)<0.00068287037037037,0,SUM(H11:J11)) -> 0 | L11: =IF(OR(F11="Congé",F11="OFF",M11="Abs",F11="Congé sans solde",F11="Férié",F11="Congé spécial",D11="Congé spécial"),0,IF(F11-E11<0,0,IF(F11-E11<=0.00068287037037037,0,F11-E11))) -> 0 | M11: =IF(AND(O11<>0,C11=""),"Abs",0) -> Abs | N11: =IFERROR(IF(OR(D11="OFF",D11="Congé",M11="Abs",D11="Congé sans solde",D11="Férié"),"",IF(O11-K11-L11>O11,O11,IF(O11-K11-L11<0,"",O11-K11-L11))),"") | O11: =IF(AG11="2H Pause déjeuner",IF(F11-D11-0.0833333333333333<0,F11-D11-0.0833333333333333+1,F11-D11-0.0833333333333333),IF(OR(AND(F11="OFF",D11="OFF"),AND(F11="Congé",D11="Congé"),AND(F11="Congé sans solde",D11="Congé sans solde"),AND(F11="Congé spécial",D11="Congé spécial"),AND(F11="Férié",D11="Férié"),AND(F11="OFF",D11="Congé"),AND(F11="OFF",D11="Congé sans solde"),AND(F11="OFF",D11="Congé spécial"),AND(F11="OFF",D11="Férié"),AND(F11="Congé",D11="OFF"),AND(F11="Congé",D11="Congé sans solde"),AND(F11="Congé",D11="Congé spécial"),AND(F11="Congé",D11="Férié"),AND(F11="Congé sans solde",D11="OFF"),AND(F11="Congé sans solde",D11="Congé"),AND(F11="Congé sans solde",D11="Congé spécial"),AND(F11="Congé sans solde",D11="Férié"),AND(F11="Congé spécial",D11="OFF"),AND(F11="Congé spécial",D11="Congé"),AND(F11="Congé spécial",D11="Congé sans solde"),AND(F11="Congé spécial",D11="Férié"),AND(F11="Férié",D11="OFF"),AND(F11="Férié",D11="Congé"),AND(F11="Férié",D11="Congé sans solde"),AND(F11="Férié",D11="Congé spécial")),0,IF(OR(F11="OFF",F11="Congé",F11="Congé spécial",F11="Congé sans solde",D11="OFF",D11="Congé",D11="Congé spécial",D11="Congé sans solde"),0.208333333333334,IF(AND(AG11="",F11-D11<0),("24:00:00"-D11)+("00:00:00"+F11)-0.0416666666666667,IF(AND(OR(AG11="Allaitement",AG11="Sans déjeuner"),F11-D11<0),("24:00:00"-D11)+("00:00:00"+F11),IF(AND(AG11="",F11-D11>0.166666666666667),F11-D11-0.0416666666666667,IF(AND(OR(AG11="Allaitement",AG11="Sans déjeuner"),F11-D11>0.166666666666667),F11-D11,F11-D11))))))) -> 0.375 | P11: =IFERROR(VLOOKUP($B11,Annuaire_roster!$B:$G,MATCH(P$1,Annuaire_roster!$B$1:$G$1,0),0),"-") -> Google Leads | Q11: 44717 | R11: =IF(M11="Abs",O11,0) -> 0.375 | S11: =SUM(R11,L11,I11,J11,W11,H11) -> 0.375 | T11: ="Sem - "&WEEKNUM(Q11,21) -> Sem - 23 | U11: =PROPER(TEXT(Q11,"mmmm")) -> June | V11: =+TEXT(Q11,"aaa") -> Sat | X11: =IFERROR(IF(M11="Abs",0,IF((D11-C11+E11-F11)<0.000694444444444444,0,(D11-C11+E11-F11))),0) -> 0 | Y11: =IFERROR(VLOOKUP(B11,Annuaire_roster!B:E,4,0),"-") -> 0 | Z11: =IFERROR(VLOOKUP(B11,Annuaire_roster!B:F,3,0),"-") -> Google Leads | AA11: =IFERROR(VLOOKUP(B11,Annuaire_roster!B:I,6,0),"-") -> 0 | AB11: =IF(AND(D11="Congé",F11="Congé"),0.333333333333333,IF(OR(AND(D11="Congé",F11<>"Congé"),(AND(F11="Congé",D11<>"Congé"))),0.166666666666667,"")) | AC11: =IF(AND(D11="Congé sans solde",F11="Congé sans solde"),0.333333333333333,IF(OR(AND(D11="Congé sans solde",F11<>"Congé sans solde"),(AND(F11="Congé sans solde",D11<>"Congé sans solde"))),0.166666666666667,"")) | AD11: =IF(AND(D11="Congé spécial",F11="Congé spécial"),0.333333333333333,IF(OR(AND(D11="Congé spécial",F11<>"Congé décès"),(AND(F11="Congé spécial",D11<>"Congé spécial"))),0.166666666666667,"")) | AE11: =IF(AND(D11="Férié",F11="Férié"),0.333333333333333,IF(OR(AND(D11="Férié",F11<>"Férié"),(AND(F11="Férié",D11<>"Férié"))),0.166666666666667,""))
A12: =VLOOKUP(B12,Annuaire_roster!B:F,5,0) -> 364 | B12: EL-AOUAQUI BOUCHRA | C12: =IFERROR(IF(COUNTIFS(Pointage_brut!$E:$E,VLOOKUP($B12,Annuaire_roster!$B:$J,9,0),Pointage_brut!$A:$A,TEXT($Q12,"yyyymmdd")*1)=0,"",MOD(_xlfn.MINIFS(Pointage_brut!$F:$F,Pointage_brut!$E:$E,VLOOKUP($B12,Annuaire_roster!$B:$J,9,0),Pointage_brut!$A:$A,TEXT($Q12,"yyyymmdd")*1),1)),"") | D12: {=IFERROR(INDEX(Planning2[],MATCH(1,(Planning2[Nom]=B12)*(Planning2[Date]=Q12),0),3),"-")} -> 0.41666667 | E12: =IFERROR(IF(COUNTIFS(Pointage_brut!$E:$E,VLOOKUP($B12,Annuaire_roster!$B:$J,9,0),Pointage_brut!$A:$A,TEXT($Q12,"yyyymmdd")*1)=0,"",MOD(_xlfn.MAXIFS(Pointage_brut!$G:$G,Pointage_brut!$E:$E,VLOOKUP($B12,Annuaire_roster!$B:$J,9,0),Pointage_brut!$A:$A,TEXT($Q12,"yyyymmdd")*1),1)),"") | F12: {=IFERROR(INDEX(Planning2[],MATCH(1,(Planning2[Nom]=B12)*(Planning2[Date]=Q12),0),4),"-")} -> 0.83333333 | I12: =IF(IF(OR(C12="",D12="Congé",D12="OFF",D12="Congé spécial"),"",IF(D12>F12,D12-C12,IF(C12-D12<0,0,C12-D12)))<0.00068287037037037,"",IF(OR(D12="Congé",D12="OFF",C12="",D12="Congé spécial"),"",IF(D12>F12,D12-C12,IF(C12-D12<0,0,C12-D12)))) | K12: =IF(SUM(H12:J12)<0.00068287037037037,0,SUM(H12:J12)) -> 0 | L12: =IF(OR(F12="Congé",F12="OFF",M12="Abs",F12="Congé sans solde",F12="Férié",F12="Congé spécial",D12="Congé spécial"),0,IF(F12-E12<0,0,IF(F12-E12<=0.00068287037037037,0,F12-E12))) -> 0 | M12: =IF(AND(O12<>0,C12=""),"Abs",0) -> Abs | N12: =IFERROR(IF(OR(D12="OFF",D12="Congé",M12="Abs",D12="Congé sans solde",D12="Férié"),"",IF(O12-K12-L12>O12,O12,IF(O12-K12-L12<0,"",O12-K12-L12))),"") | O12: =IF(AG12="2H Pause déjeuner",IF(F12-D12-0.0833333333333333<0,F12-D12-0.0833333333333333+1,F12-D12-0.0833333333333333),IF(OR(AND(F12="OFF",D12="OFF"),AND(F12="Congé",D12="Congé"),AND(F12="Congé sans solde",D12="Congé sans solde"),AND(F12="Congé spécial",D12="Congé spécial"),AND(F12="Férié",D12="Férié"),AND(F12="OFF",D12="Congé"),AND(F12="OFF",D12="Congé sans solde"),AND(F12="OFF",D12="Congé spécial"),AND(F12="OFF",D12="Férié"),AND(F12="Congé",D12="OFF"),AND(F12="Congé",D12="Congé sans solde"),AND(F12="Congé",D12="Congé spécial"),AND(F12="Congé",D12="Férié"),AND(F12="Congé sans solde",D12="OFF"),AND(F12="Congé sans solde",D12="Congé"),AND(F12="Congé sans solde",D12="Congé spécial"),AND(F12="Congé sans solde",D12="Férié"),AND(F12="Congé spécial",D12="OFF"),AND(F12="Congé spécial",D12="Congé"),AND(F12="Congé spécial",D12="Congé sans solde"),AND(F12="Congé spécial",D12="Férié"),AND(F12="Férié",D12="OFF"),AND(F12="Férié",D12="Congé"),AND(F12="Férié",D12="Congé sans solde"),AND(F12="Férié",D12="Congé spécial")),0,IF(OR(F12="OFF",F12="Congé",F12="Congé spécial",F12="Congé sans solde",D12="OFF",D12="Congé",D12="Congé spécial",D12="Congé sans solde"),0.208333333333334,IF(AND(AG12="",F12-D12<0),("24:00:00"-D12)+("00:00:00"+F12)-0.0416666666666667,IF(AND(OR(AG12="Allaitement",AG12="Sans déjeuner"),F12-D12<0),("24:00:00"-D12)+("00:00:00"+F12),IF(AND(AG12="",F12-D12>0.166666666666667),F12-D12-0.0416666666666667,IF(AND(OR(AG12="Allaitement",AG12="Sans déjeuner"),F12-D12>0.166666666666667),F12-D12,F12-D12))))))) -> 0.375 | P12: =IFERROR(VLOOKUP($B12,Annuaire_roster!$B:$G,MATCH(P$1,Annuaire_roster!$B$1:$G$1,0),0),"-") -> Google Leads | Q12: 44717 | R12: =IF(M12="Abs",O12,0) -> 0.375 | S12: =SUM(R12,L12,I12,J12,W12,H12) -> 0.375 | T12: ="Sem - "&WEEKNUM(Q12,21) -> Sem - 23 | U12: =PROPER(TEXT(Q12,"mmmm")) -> June | V12: =+TEXT(Q12,"aaa") -> Sat | X12: =IFERROR(IF(M12="Abs",0,IF((D12-C12+E12-F12)<0.000694444444444444,0,(D12-C12+E12-F12))),0) -> 0 | Y12: =IFERROR(VLOOKUP(B12,Annuaire_roster!B:E,4,0),"-") -> OUAQERROUCH Nour-El Houda | Z12: =IFERROR(VLOOKUP(B12,Annuaire_roster!B:F,3,0),"-") -> Google Leads | AA12: =IFERROR(VLOOKUP(B12,Annuaire_roster!B:I,6,0),"-") -> Forfaitaire | AB12: =IF(AND(D12="Congé",F12="Congé"),0.333333333333333,IF(OR(AND(D12="Congé",F12<>"Congé"),(AND(F12="Congé",D12<>"Congé"))),0.166666666666667,"")) | AC12: =IF(AND(D12="Congé sans solde",F12="Congé sans solde"),0.333333333333333,IF(OR(AND(D12="Congé sans solde",F12<>"Congé sans solde"),(AND(F12="Congé sans solde",D12<>"Congé sans solde"))),0.166666666666667,"")) | AD12: =IF(AND(D12="Congé spécial",F12="Congé spécial"),0.333333333333333,IF(OR(AND(D12="Congé spécial",F12<>"Congé décès"),(AND(F12="Congé spécial",D12<>"Congé spécial"))),0.166666666666667,"")) | AE12: =IF(AND(D12="Férié",F12="Férié"),0.333333333333333,IF(OR(AND(D12="Férié",F12<>"Férié"),(AND(F12="Férié",D12<>"Férié"))),0.166666666666667,""))
A13: =VLOOKUP(B13,Annuaire_roster!B:F,5,0) -> 1009 | B13: ZITOUNI LAMYA | C13: =IFERROR(IF(COUNTIFS(Pointage_brut!$E:$E,VLOOKUP($B13,Annuaire_roster!$B:$J,9,0),Pointage_brut!$A:$A,TEXT($Q13,"yyyymmdd")*1)=0,"",MOD(_xlfn.MINIFS(Pointage_brut!$F:$F,Pointage_brut!$E:$E,VLOOKUP($B13,Annuaire_roster!$B:$J,9,0),Pointage_brut!$A:$A,TEXT($Q13,"yyyymmdd")*1),1)),"") | D13: {=IFERROR(INDEX(Planning2[],MATCH(1,(Planning2[Nom]=B13)*(Planning2[Date]=Q13),0),3),"-")} -> 0.41666667 | E13: =IFERROR(IF(COUNTIFS(Pointage_brut!$E:$E,VLOOKUP($B13,Annuaire_roster!$B:$J,9,0),Pointage_brut!$A:$A,TEXT($Q13,"yyyymmdd")*1)=0,"",MOD(_xlfn.MAXIFS(Pointage_brut!$G:$G,Pointage_brut!$E:$E,VLOOKUP($B13,Annuaire_roster!$B:$J,9,0),Pointage_brut!$A:$A,TEXT($Q13,"yyyymmdd")*1),1)),"") | F13: {=IFERROR(INDEX(Planning2[],MATCH(1,(Planning2[Nom]=B13)*(Planning2[Date]=Q13),0),4),"-")} -> 0.83333333 | I13: =IF(IF(OR(C13="",D13="Congé",D13="OFF",D13="Congé spécial"),"",IF(D13>F13,D13-C13,IF(C13-D13<0,0,C13-D13)))<0.00068287037037037,"",IF(OR(D13="Congé",D13="OFF",C13="",D13="Congé spécial"),"",IF(D13>F13,D13-C13,IF(C13-D13<0,0,C13-D13)))) | K13: =IF(SUM(H13:J13)<0.00068287037037037,0,SUM(H13:J13)) -> 0 | L13: =IF(OR(F13="Congé",F13="OFF",M13="Abs",F13="Congé sans solde",F13="Férié",F13="Congé spécial",D13="Congé spécial"),0,IF(F13-E13<0,0,IF(F13-E13<=0.00068287037037037,0,F13-E13))) -> 0 | M13: =IF(AND(O13<>0,C13=""),"Abs",0) -> Abs | N13: =IFERROR(IF(OR(D13="OFF",D13="Congé",M13="Abs",D13="Congé sans solde",D13="Férié"),"",IF(O13-K13-L13>O13,O13,IF(O13-K13-L13<0,"",O13-K13-L13))),"") | O13: =IF(AG13="2H Pause déjeuner",IF(F13-D13-0.0833333333333333<0,F13-D13-0.0833333333333333+1,F13-D13-0.0833333333333333),IF(OR(AND(F13="OFF",D13="OFF"),AND(F13="Congé",D13="Congé"),AND(F13="Congé sans solde",D13="Congé sans solde"),AND(F13="Congé spécial",D13="Congé spécial"),AND(F13="Férié",D13="Férié"),AND(F13="OFF",D13="Congé"),AND(F13="OFF",D13="Congé sans solde"),AND(F13="OFF",D13="Congé spécial"),AND(F13="OFF",D13="Férié"),AND(F13="Congé",D13="OFF"),AND(F13="Congé",D13="Congé sans solde"),AND(F13="Congé",D13="Congé spécial"),AND(F13="Congé",D13="Férié"),AND(F13="Congé sans solde",D13="OFF"),AND(F13="Congé sans solde",D13="Congé"),AND(F13="Congé sans solde",D13="Congé spécial"),AND(F13="Congé sans solde",D13="Férié"),AND(F13="Congé spécial",D13="OFF"),AND(F13="Congé spécial",D13="Congé"),AND(F13="Congé spécial",D13="Congé sans solde"),AND(F13="Congé spécial",D13="Férié"),AND(F13="Férié",D13="OFF"),AND(F13="Férié",D13="Congé"),AND(F13="Férié",D13="Congé sans solde"),AND(F13="Férié",D13="Congé spécial")),0,IF(OR(F13="OFF",F13="Congé",F13="Congé spécial",F13="Congé sans solde",D13="OFF",D13="Congé",D13="Congé spécial",D13="Congé sans solde"),0.208333333333334,IF(AND(AG13="",F13-D13<0),("24:00:00"-D13)+("00:00:00"+F13)-0.0416666666666667,IF(AND(OR(AG13="Allaitement",AG13="Sans déjeuner"),F13-D13<0),("24:00:00"-D13)+("00:00:00"+F13),IF(AND(AG13="",F13-D13>0.166666666666667),F13-D13-0.0416666666666667,IF(AND(OR(AG13="Allaitement",AG13="Sans déjeuner"),F13-D13>0.166666666666667),F13-D13,F13-D13))))))) -> 0.375 | P13: =IFERROR(VLOOKUP($B13,Annuaire_roster!$B:$G,MATCH(P$1,Annuaire_roster!$B$1:$G$1,0),0),"-") -> Google Leads | Q13: 44717 | R13: =IF(M13="Abs",O13,0) -> 0.375 | S13: =SUM(R13,L13,I13,J13,W13,H13) -> 0.375 | T13: ="Sem - "&WEEKNUM(Q13,21) -> Sem - 23 | U13: =PROPER(TEXT(Q13,"mmmm")) -> June | V13: =+TEXT(Q13,"aaa") -> Sat | X13: =IFERROR(IF(M13="Abs",0,IF((D13-C13+E13-F13)<0.000694444444444444,0,(D13-C13+E13-F13))),0) -> 0 | Y13: =IFERROR(VLOOKUP(B13,Annuaire_roster!B:E,4,0),"-") -> OUAQERROUCH Nour-El Houda | Z13: =IFERROR(VLOOKUP(B13,Annuaire_roster!B:F,3,0),"-") -> Google Leads | AA13: =IFERROR(VLOOKUP(B13,Annuaire_roster!B:I,6,0),"-") -> Forfaitaire | AB13: =IF(AND(D13="Congé",F13="Congé"),0.333333333333333,IF(OR(AND(D13="Congé",F13<>"Congé"),(AND(F13="Congé",D13<>"Congé"))),0.166666666666667,"")) | AC13: =IF(AND(D13="Congé sans solde",F13="Congé sans solde"),0.333333333333333,IF(OR(AND(D13="Congé sans solde",F13<>"Congé sans solde"),(AND(F13="Congé sans solde",D13<>"Congé sans solde"))),0.166666666666667,"")) | AD13: =IF(AND(D13="Congé spécial",F13="Congé spécial"),0.333333333333333,IF(OR(AND(D13="Congé spécial",F13<>"Congé décès"),(AND(F13="Congé spécial",D13<>"Congé spécial"))),0.166666666666667,"")) | AE13: =IF(AND(D13="Férié",F13="Férié"),0.333333333333333,IF(OR(AND(D13="Férié",F13<>"Férié"),(AND(F13="Férié",D13<>"Férié"))),0.166666666666667,""))
... A20: =VLOOKUP(B20,Annuaire_roster!B:F,5,0) -> 0 | B20: AINELKITANE ZINEB | C20: =IFERROR(IF(COUNTIFS(Pointage_brut!$E:$E,VLOOKUP($B20,Annuaire_roster!$B:$J,9,0),Pointage_brut!$A:$A,TEXT($Q20,"yyyymmdd")*1)=0,"",MOD(_xlfn.MINIFS(Pointage_brut!$F:$F,Pointage_brut!$E:$E,VLOOKUP($B20,Annuaire_roster!$B:$J,9,0),Pointage_brut!$A:$A,TEXT($Q20,"yyyymmdd")*1),1)),"") | D20: {=IFERROR(INDEX(Planning2[],MATCH(1,(Planning2[Nom]=B20)*(Planning2[Date]=Q20),0),3),"-")} -> 0.41666667 | E20: =IFERROR(IF(COUNTIFS(Pointage_brut!$E:$E,VLOOKUP($B20,Annuaire_roster!$B:$J,9,0),Pointage_brut!$A:$A,TEXT($Q20,"yyyymmdd")*1)=0,"",MOD(_xlfn.MAXIFS(Pointage_brut!$G:$G,Pointage_brut!$E:$E,VLOOKUP($B20,Annuaire_roster!$B:$J,9,0),Pointage_brut!$A:$A,TEXT($Q20,"yyyymmdd")*1),1)),"") | F20: {=IFERROR(INDEX(Planning2[],MATCH(1,(Planning2[Nom]=B20)*(Planning2[Date]=Q20),0),4),"-")} -> 0.83333333 | I20: =IF(IF(OR(C20="",D20="Congé",D20="OFF",D20="Congé spécial"),"",IF(D20>F20,D20-C20,IF(C20-D20<0,0,C20-D20)))<0.00068287037037037,"",IF(OR(D20="Congé",D20="OFF",C20="",D20="Congé spécial"),"",IF(D20>F20,D20-C20,IF(C20-D20<0,0,C20-D20)))) | K20: =IF(SUM(H20:J20)<0.00068287037037037,0,SUM(H20:J20)) -> 0 | L20: =IF(OR(F20="Congé",F20="OFF",M20="Abs",F20="Congé sans solde",F20="Férié",F20="Congé spécial",D20="Congé spécial"),0,IF(F20-E20<0,0,IF(F20-E20<=0.00068287037037037,0,F20-E20))) -> 0 | M20: =IF(AND(O20<>0,C20=""),"Abs",0) -> Abs | N20: =IFERROR(IF(OR(D20="OFF",D20="Congé",M20="Abs",D20="Congé sans solde",D20="Férié"),"",IF(O20-K20-L20>O20,O20,IF(O20-K20-L20<0,"",O20-K20-L20))),"") | O20: =IF(AG20="2H Pause déjeuner",IF(F20-D20-0.0833333333333333<0,F20-D20-0.0833333333333333+1,F20-D20-0.0833333333333333),IF(OR(AND(F20="OFF",D20="OFF"),AND(F20="Congé",D20="Congé"),AND(F20="Congé sans solde",D20="Congé sans solde"),AND(F20="Congé spécial",D20="Congé spécial"),AND(F20="Férié",D20="Férié"),AND(F20="OFF",D20="Congé"),AND(F20="OFF",D20="Congé sans solde"),AND(F20="OFF",D20="Congé spécial"),AND(F20="OFF",D20="Férié"),AND(F20="Congé",D20="OFF"),AND(F20="Congé",D20="Congé sans solde"),AND(F20="Congé",D20="Congé spécial"),AND(F20="Congé",D20="Férié"),AND(F20="Congé sans solde",D20="OFF"),AND(F20="Congé sans solde",D20="Congé"),AND(F20="Congé sans solde",D20="Congé spécial"),AND(F20="Congé sans solde",D20="Férié"),AND(F20="Congé spécial",D20="OFF"),AND(F20="Congé spécial",D20="Congé"),AND(F20="Congé spécial",D20="Congé sans solde"),AND(F20="Congé spécial",D20="Férié"),AND(F20="Férié",D20="OFF"),AND(F20="Férié",D20="Congé"),AND(F20="Férié",D20="Congé sans solde"),AND(F20="Férié",D20="Congé spécial")),0,IF(OR(F20="OFF",F20="Congé",F20="Congé spécial",F20="Congé sans solde",D20="OFF",D20="Congé",D20="Congé spécial",D20="Congé sans solde"),0.208333333333334,IF(AND(AG20="",F20-D20<0),("24:00:00"-D20)+("00:00:00"+F20)-0.0416666666666667,IF(AND(OR(AG20="Allaitement",AG20="Sans déjeuner"),F20-D20<0),("24:00:00"-D20)+("00:00:00"+F20),IF(AND(AG20="",F20-D20>0.166666666666667),F20-D20-0.0416666666666667,IF(AND(OR(AG20="Allaitement",AG20="Sans déjeuner"),F20-D20>0.166666666666667),F20-D20,F20-D20))))))) -> 0.375 | P20: =IFERROR(VLOOKUP($B20,Annuaire_roster!$B:$G,MATCH(P$1,Annuaire_roster!$B$1:$G$1,0),0),"-") -> Google Leads | Q20: 44717 | R20: =IF(M20="Abs",O20,0) -> 0.375 | S20: =SUM(R20,L20,I20,J20,W20,H20) -> 0.375 | T20: ="Sem - "&WEEKNUM(Q20,21) -> Sem - 23 | U20: =PROPER(TEXT(Q20,"mmmm")) -> June | V20: =+TEXT(Q20,"aaa") -> Sat | X20: =IFERROR(IF(M20="Abs",0,IF((D20-C20+E20-F20)<0.000694444444444444,0,(D20-C20+E20-F20))),0) -> 0 | Y20: =IFERROR(VLOOKUP(B20,Annuaire_roster!B:E,4,0),"-") -> 0 | Z20: =IFERROR(VLOOKUP(B20,Annuaire_roster!B:F,3,0),"-") -> Google Leads | AA20: =IFERROR(VLOOKUP(B20,Annuaire_roster!B:I,6,0),"-") -> 0 | AB20: =IF(AND(D20="Congé",F20="Congé"),0.333333333333333,IF(OR(AND(D20="Congé",F20<>"Congé"),(AND(F20="Congé",D20<>"Congé"))),0.166666666666667,"")) | AC20: =IF(AND(D20="Congé sans solde",F20="Congé sans solde"),0.333333333333333,IF(OR(AND(D20="Congé sans solde",F20<>"Congé sans solde"),(AND(F20="Congé sans solde",D20<>"Congé sans solde"))),0.166666666666667,"")) | AD20: =IF(AND(D20="Congé spécial",F20="Congé spécial"),0.333333333333333,IF(OR(AND(D20="Congé spécial",F20<>"Congé décès"),(AND(F20="Congé spécial",D20<>"Congé spécial"))),0.166666666666667,"")) | AE20: =IF(AND(D20="Férié",F20="Férié"),0.333333333333333,IF(OR(AND(D20="Férié",F20<>"Férié"),(AND(F20="Férié",D20<>"Férié"))),0.166666666666667,""))
